Workbook

Sheet PPT
F1: LEGEND | G1: Submitted | J1: Approved | M1: In Process | AA1: LEGEND: | AD1: Submitted | AG1: Approved | AJ1: In Process
G2: Overall | K2: CIVIL | N2: Mechanial | Q2: Electrical | T2: Electrical | AA2: S no | AB2: Syst no | AC2: Description | AD2: Overall | AG2: CIVIL | AJ2: Mechanical | AM2: Electrical | AP2: C&I
D3: S no | E3: Syst no | F3: Description | G3: =SUM(G4:G30) -> 95 | H3: =SUM(H4:H30) -> 26 | I3: =SUM(I4:I30) -> 69 | J3: =SUM(J4:J30) -> 27 | K3: =SUM(K4:K30) -> 0 | L3: =SUM(L4:L30) -> 27 | M3: =SUM(M4:M30) -> 33 | N3: =SUM(N4:N30) -> 6 | ... U3: =SUM(U4:U30) -> 2 | AD3: =SUM(AD4:AD30) -> 88 | AE3: =SUM(AE4:AE30) -> 23 | AF3: =SUM(AF4:AF30) -> 65 | AG3: =SUM(AG4:AG30) -> 24 | AH3: =SUM(AH4:AH30) -> 0 | AI3: =SUM(AI4:AI30) -> 24 | AJ3: =SUM(AJ4:AJ30) -> 29 | AK3: =SUM(AK4:AK30) -> 4 | ... AR3: =SUM(AR4:AR30) -> 2
D4: 1 | E4: 1.1 | F4: Desal | G4: =J4+M4+P4+S4 -> 13 | H4: =K4+N4+Q4+T4 -> 4 | I4: =L4+O4+R4+U4 -> 9 | J4: =VLOOKUP(PPT!$F4,'LCB MIS overall'!$K$8:$BL$35,28,0)-VLOOKUP(PPT!$F4,'LCB MIS overall'!$K$8:$BL$35,29,0) -> 4 | K4: =VLOOKUP(PPT!$F4,'LCB MIS overall'!$K$8:$BL$35,30,0) -> 0 | L4: =J4-K4 -> 4 | M4: =VLOOKUP(PPT!$F4,'LCB MIS overall'!$K$8:$BL$35,36,0)-VLOOKUP(PPT!$F4,'LCB MIS overall'!$K$8:$BL$35,37,0) -> 9 | N4: =VLOOKUP(PPT!$F4,'LCB MIS overall'!$K$8:$BL$35,38,0) -> 4 | O4: =M4-N4 -> 5 | P4: =VLOOKUP(PPT!$F4,'LCB MIS overall'!$K$8:$BL$35,44,0)-VLOOKUP(PPT!$F4,'LCB MIS overall'!$K$8:$BL$35,45,0) -> 0 | Q4: =VLOOKUP(PPT!$F4,'LCB MIS overall'!$K$8:$BL$35,46,0) -> 0 | R4: =P4-Q4 -> 0 | S4: =VLOOKUP(PPT!$F4,'LCB MIS overall'!$K$8:$BL$35,52,0)-VLOOKUP(PPT!$F4,'LCB MIS overall'!$K$8:$BL$35,53,0) -> 0 | T4: =VLOOKUP(PPT!$F4,'LCB MIS overall'!$K$8:$BL$35,54,0) -> 0 | U4: =S4-T4 -> 0 | AA4: 1 | AB4: 1.1 | AC4: Desal | AD4: =AG4+AJ4+AM4+AP4 -> 13 | AE4: =AH4+AK4+AN4+AQ4 -> 3 | AF4: =AI4+AL4+AO4+AR4 -> 10 | AG4: 4 | AH4: 0 | AI4: 4 | AJ4: 9 | AK4: 3 | AL4: 6 | AM4: 0 | AN4: 0 | AO4: 0 | AP4: 0 | AQ4: 0 | AR4: 0
D5: 2 | E5: 1.2 | F5: DM | G5: =J5+M5+P5+S5 -> 16 | H5: =K5+N5+Q5+T5 -> 0 | I5: =L5+O5+R5+U5 -> 16 | J5: =VLOOKUP(PPT!$F5,'LCB MIS overall'!$K$8:$BL$35,28,0)-VLOOKUP(PPT!$F5,'LCB MIS overall'!$K$8:$BL$35,29,0) -> 8 | K5: =VLOOKUP(PPT!$F5,'LCB MIS overall'!$K$8:$BL$35,30,0) -> 0 | L5: =J5-K5 -> 8 | M5: =VLOOKUP(PPT!$F5,'LCB MIS overall'!$K$8:$BL$35,36,0)-VLOOKUP(PPT!$F5,'LCB MIS overall'!$K$8:$BL$35,37,0) -> 8 | N5: =VLOOKUP(PPT!$F5,'LCB MIS overall'!$K$8:$BL$35,38,0) -> 0 | O5: =M5-N5 -> 8 | P5: =VLOOKUP(PPT!$F5,'LCB MIS overall'!$K$8:$BL$35,44,0)-VLOOKUP(PPT!$F5,'LCB MIS overall'!$K$8:$BL$35,45,0) -> 0 | Q5: =VLOOKUP(PPT!$F5,'LCB MIS overall'!$K$8:$BL$35,46,0) -> 0 | R5: =P5-Q5 -> 0 | S5: =VLOOKUP(PPT!$F5,'LCB MIS overall'!$K$8:$BL$35,52,0)-VLOOKUP(PPT!$F5,'LCB MIS overall'!$K$8:$BL$35,53,0) -> 0 | T5: =VLOOKUP(PPT!$F5,'LCB MIS overall'!$K$8:$BL$35,54,0) -> 0 | U5: =S5-T5 -> 0 | AA5: 2 | AB5: 1.2 | AC5: DM | AD5: =AG5+AJ5+AM5+AP5 -> 16 | AE5: =AH5+AK5+AN5+AQ5 -> 0 | AF5: =AI5+AL5+AO5+AR5 -> 16 | AG5: 8 | AH5: 0 | AI5: 8 | AJ5: 8 | AK5: 0 | AL5: 8 | AM5: 0 | AN5: 0 | AO5: 0 | AP5: 0 | AQ5: 0 | AR5: 0
D6: 3 | E6: 1.3 | F6: 01 UGD | G6: =J6+M6+P6+S6 -> 3 | H6: =K6+N6+Q6+T6 -> 0 | I6: =L6+O6+R6+U6 -> 3 | J6: =VLOOKUP(PPT!$F6,'LCB MIS overall'!$K$8:$BL$35,28,0)-VLOOKUP(PPT!$F6,'LCB MIS overall'!$K$8:$BL$35,29,0) -> 1 | K6: =VLOOKUP(PPT!$F6,'LCB MIS overall'!$K$8:$BL$35,30,0) -> 0 | L6: =J6-K6 -> 1 | M6: =VLOOKUP(PPT!$F6,'LCB MIS overall'!$K$8:$BL$35,36,0)-VLOOKUP(PPT!$F6,'LCB MIS overall'!$K$8:$BL$35,37,0) -> 2 | N6: =VLOOKUP(PPT!$F6,'LCB MIS overall'!$K$8:$BL$35,38,0) -> 0 | O6: =M6-N6 -> 2 | P6: =VLOOKUP(PPT!$F6,'LCB MIS overall'!$K$8:$BL$35,44,0)-VLOOKUP(PPT!$F6,'LCB MIS overall'!$K$8:$BL$35,45,0) -> 0 | Q6: =VLOOKUP(PPT!$F6,'LCB MIS overall'!$K$8:$BL$35,46,0) -> 0 | R6: =P6-Q6 -> 0 | S6: =VLOOKUP(PPT!$F6,'LCB MIS overall'!$K$8:$BL$35,52,0)-VLOOKUP(PPT!$F6,'LCB MIS overall'!$K$8:$BL$35,53,0) -> 0 | T6: =VLOOKUP(PPT!$F6,'LCB MIS overall'!$K$8:$BL$35,54,0) -> 0 | U6: =S6-T6 -> 0 | AA6: 3 | AB6: 1.3 | AC6: 01 UGD | AD6: =AG6+AJ6+AM6+AP6 -> 3 | AE6: =AH6+AK6+AN6+AQ6 -> 0 | AF6: =AI6+AL6+AO6+AR6 -> 3 | AG6: 1 | AH6: 0 | AI6: 1 | AJ6: 2 | AK6: 0 | AL6: 2 | AM6: 0 | AN6: 0 | AO6: 0 | AP6: 0 | AQ6: 0 | AR6: 0
D7: 4 | E7: 1.4 | F7: Chemical Lab | G7: =J7+M7+P7+S7 -> 4 | H7: =K7+N7+Q7+T7 -> 1 | I7: =L7+O7+R7+U7 -> 3 | J7: =VLOOKUP(PPT!$F7,'LCB MIS overall'!$K$8:$BL$35,28,0)-VLOOKUP(PPT!$F7,'LCB MIS overall'!$K$8:$BL$35,29,0) -> 1 | K7: =VLOOKUP(PPT!$F7,'LCB MIS overall'!$K$8:$BL$35,30,0) -> 0 | L7: =J7-K7 -> 1 | M7: =VLOOKUP(PPT!$F7,'LCB MIS overall'!$K$8:$BL$35,36,0)-VLOOKUP(PPT!$F7,'LCB MIS overall'!$K$8:$BL$35,37,0) -> 3 | N7: =VLOOKUP(PPT!$F7,'LCB MIS overall'!$K$8:$BL$35,38,0) -> 1 | O7: =M7-N7 -> 2 | P7: =VLOOKUP(PPT!$F7,'LCB MIS overall'!$K$8:$BL$35,44,0)-VLOOKUP(PPT!$F7,'LCB MIS overall'!$K$8:$BL$35,45,0) -> 0 | Q7: =VLOOKUP(PPT!$F7,'LCB MIS overall'!$K$8:$BL$35,46,0) -> 0 | R7: =P7-Q7 -> 0 | S7: =VLOOKUP(PPT!$F7,'LCB MIS overall'!$K$8:$BL$35,52,0)-VLOOKUP(PPT!$F7,'LCB MIS overall'!$K$8:$BL$35,53,0) -> 0 | T7: =VLOOKUP(PPT!$F7,'LCB MIS overall'!$K$8:$BL$35,54,0) -> 0 | U7: =S7-T7 -> 0 | AA7: 4 | AB7: 1.4 | AC7: Chemical Lab | AD7: =AG7+AJ7+AM7+AP7 -> 3 | AE7: =AH7+AK7+AN7+AQ7 -> 0 | AF7: =AI7+AL7+AO7+AR7 -> 3 | AG7: 1 | AH7: 0 | AI7: 1 | AJ7: 2 | AK7: 0 | AL7: 2 | AM7: 0 | AN7: 0 | AO7: 0 | AP7: 0 | AQ7: 0 | AR7: 0
D8: 5 | E8: 1.5 | F8: Hydrogen | G8: =J8+M8+P8+S8 -> 0 | H8: =K8+N8+Q8+T8 -> 0 | I8: =L8+O8+R8+U8 -> 0 | J8: =VLOOKUP(PPT!$F8,'LCB MIS overall'!$K$8:$BL$35,28,0)-VLOOKUP(PPT!$F8,'LCB MIS overall'!$K$8:$BL$35,29,0) -> 0 | K8: =VLOOKUP(PPT!$F8,'LCB MIS overall'!$K$8:$BL$35,30,0) -> 0 | L8: =J8-K8 -> 0 | M8: =VLOOKUP(PPT!$F8,'LCB MIS overall'!$K$8:$BL$35,36,0)-VLOOKUP(PPT!$F8,'LCB MIS overall'!$K$8:$BL$35,37,0) -> 0 | N8: =VLOOKUP(PPT!$F8,'LCB MIS overall'!$K$8:$BL$35,38,0) -> 0 | O8: =M8-N8 -> 0 | P8: =VLOOKUP(PPT!$F8,'LCB MIS overall'!$K$8:$BL$35,44,0)-VLOOKUP(PPT!$F8,'LCB MIS overall'!$K$8:$BL$35,45,0) -> 0 | Q8: =VLOOKUP(PPT!$F8,'LCB MIS overall'!$K$8:$BL$35,46,0) -> 0 | R8: =P8-Q8 -> 0 | S8: =VLOOKUP(PPT!$F8,'LCB MIS overall'!$K$8:$BL$35,52,0)-VLOOKUP(PPT!$F8,'LCB MIS overall'!$K$8:$BL$35,53,0) -> 0 | T8: =VLOOKUP(PPT!$F8,'LCB MIS overall'!$K$8:$BL$35,54,0) -> 0 | U8: =S8-T8 -> 0 | AA8: 5 | AB8: 1.5 | AC8: Hydrogen | AD8: =AG8+AJ8+AM8+AP8 -> 0 | AE8: =AH8+AK8+AN8+AQ8 -> 0 | AF8: =AI8+AL8+AO8+AR8 -> 0 | AG8: 0 | AH8: 0 | AI8: 0 | AJ8: 0 | AK8: 0 | AL8: 0 | AM8: 0 | AN8: 0 | AO8: 0 | AP8: 0 | AQ8: 0 | AR8: 0
D9: 6 | E9: 1.6 | F9: Nitrogen | G9: =J9+M9+P9+S9 -> 0 | H9: =K9+N9+Q9+T9 -> 0 | I9: =L9+O9+R9+U9 -> 0 | J9: =VLOOKUP(PPT!$F9,'LCB MIS overall'!$K$8:$BL$35,28,0)-VLOOKUP(PPT!$F9,'LCB MIS overall'!$K$8:$BL$35,29,0) -> 0 | K9: =VLOOKUP(PPT!$F9,'LCB MIS overall'!$K$8:$BL$35,30,0) -> 0 | L9: =J9-K9 -> 0 | M9: =VLOOKUP(PPT!$F9,'LCB MIS overall'!$K$8:$BL$35,36,0)-VLOOKUP(PPT!$F9,'LCB MIS overall'!$K$8:$BL$35,37,0) -> 0 | N9: =VLOOKUP(PPT!$F9,'LCB MIS overall'!$K$8:$BL$35,38,0) -> 0 | O9: =M9-N9 -> 0 | P9: =VLOOKUP(PPT!$F9,'LCB MIS overall'!$K$8:$BL$35,44,0)-VLOOKUP(PPT!$F9,'LCB MIS overall'!$K$8:$BL$35,45,0) -> 0 | Q9: =VLOOKUP(PPT!$F9,'LCB MIS overall'!$K$8:$BL$35,46,0) -> 0 | R9: =P9-Q9 -> 0 | S9: =VLOOKUP(PPT!$F9,'LCB MIS overall'!$K$8:$BL$35,52,0)-VLOOKUP(PPT!$F9,'LCB MIS overall'!$K$8:$BL$35,53,0) -> 0 | T9: =VLOOKUP(PPT!$F9,'LCB MIS overall'!$K$8:$BL$35,54,0) -> 0 | U9: =S9-T9 -> 0 | AA9: 6 | AB9: 1.6 | AC9: Nitrogen | AD9: =AG9+AJ9+AM9+AP9 -> 0 | AE9: =AH9+AK9+AN9+AQ9 -> 0 | AF9: =AI9+AL9+AO9+AR9 -> 0 | AG9: 0 | AH9: 0 | AI9: 0 | AJ9: 0 | AK9: 0 | AL9: 0 | AM9: 0 | AN9: 0 | AO9: 0 | AP9: 0 | AQ9: 0 | AR9: 0
D10: 7 | E10: 1.7 | F10: 01 USK | G10: =J10+M10+P10+S10 -> 0 | H10: =K10+N10+Q10+T10 -> 0 | I10: =L10+O10+R10+U10 -> 0 | J10: =VLOOKUP(PPT!$F10,'LCB MIS overall'!$K$8:$BL$35,28,0)-VLOOKUP(PPT!$F10,'LCB MIS overall'!$K$8:$BL$35,29,0) -> 0 | K10: =VLOOKUP(PPT!$F10,'LCB MIS overall'!$K$8:$BL$35,30,0) -> 0 | L10: =J10-K10 -> 0 | M10: =VLOOKUP(PPT!$F10,'LCB MIS overall'!$K$8:$BL$35,36,0)-VLOOKUP(PPT!$F10,'LCB MIS overall'!$K$8:$BL$35,37,0) -> 0 | N10: =VLOOKUP(PPT!$F10,'LCB MIS overall'!$K$8:$BL$35,38,0) -> 0 | O10: =M10-N10 -> 0 | P10: =VLOOKUP(PPT!$F10,'LCB MIS overall'!$K$8:$BL$35,44,0)-VLOOKUP(PPT!$F10,'LCB MIS overall'!$K$8:$BL$35,45,0) -> 0 | Q10: =VLOOKUP(PPT!$F10,'LCB MIS overall'!$K$8:$BL$35,46,0) -> 0 | R10: =P10-Q10 -> 0 | S10: =VLOOKUP(PPT!$F10,'LCB MIS overall'!$K$8:$BL$35,52,0)-VLOOKUP(PPT!$F10,'LCB MIS overall'!$K$8:$BL$35,53,0) -> 0 | T10: =VLOOKUP(PPT!$F10,'LCB MIS overall'!$K$8:$BL$35,54,0) -> 0 | U10: =S10-T10 -> 0 | AA10: 7 | AB10: 1.7 | AC10: 01 USK | AD10: =AG10+AJ10+AM10+AP10 -> 0 | AE10: =AH10+AK10+AN10+AQ10 -> 0 | AF10: =AI10+AL10+AO10+AR10 -> 0 | AG10: 0 | AH10: 0 | AI10: 0 | AJ10: 0 | AK10: 0 | AL10: 0 | AM10: 0 | AN10: 0 | AO10: 0 | AP10: 0 | AQ10: 0 | AR10: 0
D11: 8 | E11: 1.8 | F11: DIESEL AND OIL | G11: =J11+M11+P11+S11 -> 0 | H11: =K11+N11+Q11+T11 -> 0 | I11: =L11+O11+R11+U11 -> 0 | J11: =VLOOKUP(PPT!$F11,'LCB MIS overall'!$K$8:$BL$35,28,0)-VLOOKUP(PPT!$F11,'LCB MIS overall'!$K$8:$BL$35,29,0) -> 0 | K11: =VLOOKUP(PPT!$F11,'LCB MIS overall'!$K$8:$BL$35,30,0) -> 0 | L11: =J11-K11 -> 0 | M11: =VLOOKUP(PPT!$F11,'LCB MIS overall'!$K$8:$BL$35,36,0)-VLOOKUP(PPT!$F11,'LCB MIS overall'!$K$8:$BL$35,37,0) -> 0 | N11: =VLOOKUP(PPT!$F11,'LCB MIS overall'!$K$8:$BL$35,38,0) -> 0 | O11: =M11-N11 -> 0 | P11: =VLOOKUP(PPT!$F11,'LCB MIS overall'!$K$8:$BL$35,44,0)-VLOOKUP(PPT!$F11,'LCB MIS overall'!$K$8:$BL$35,45,0) -> 0 | Q11: =VLOOKUP(PPT!$F11,'LCB MIS overall'!$K$8:$BL$35,46,0) -> 0 | R11: =P11-Q11 -> 0 | S11: =VLOOKUP(PPT!$F11,'LCB MIS overall'!$K$8:$BL$35,52,0)-VLOOKUP(PPT!$F11,'LCB MIS overall'!$K$8:$BL$35,53,0) -> 0 | T11: =VLOOKUP(PPT!$F11,'LCB MIS overall'!$K$8:$BL$35,54,0) -> 0 | U11: =S11-T11 -> 0 | AA11: 8 | AB11: 1.8 | AC11: DIESEL AND OIL | AD11: =AG11+AJ11+AM11+AP11 -> 0 | AE11: =AH11+AK11+AN11+AQ11 -> 0 | AF11: =AI11+AL11+AO11+AR11 -> 0 | AG11: 0 | AH11: 0 | AI11: 0 | AJ11: 0 | AK11: 0 | AL11: 0 | AM11: 0 | AN11: 0 | AO11: 0 | AP11: 0 | AQ11: 0 | AR11: 0
D12: 9 | E12: 1.9 | F12: WWNS | G12: =J12+M12+P12+S12 -> 3 | H12: =K12+N12+Q12+T12 -> 0 | I12: =L12+O12+R12+U12 -> 3 | J12: =VLOOKUP(PPT!$F12,'LCB MIS overall'!$K$8:$BL$35,28,0)-VLOOKUP(PPT!$F12,'LCB MIS overall'!$K$8:$BL$35,29,0) -> 3 | K12: =VLOOKUP(PPT!$F12,'LCB MIS overall'!$K$8:$BL$35,30,0) -> 0 | L12: =J12-K12 -> 3 | M12: =VLOOKUP(PPT!$F12,'LCB MIS overall'!$K$8:$BL$35,36,0)-VLOOKUP(PPT!$F12,'LCB MIS overall'!$K$8:$BL$35,37,0) -> 0 | N12: =VLOOKUP(PPT!$F12,'LCB MIS overall'!$K$8:$BL$35,38,0) -> 0 | O12: =M12-N12 -> 0 | P12: =VLOOKUP(PPT!$F12,'LCB MIS overall'!$K$8:$BL$35,44,0)-VLOOKUP(PPT!$F12,'LCB MIS overall'!$K$8:$BL$35,45,0) -> 0 | Q12: =VLOOKUP(PPT!$F12,'LCB MIS overall'!$K$8:$BL$35,46,0) -> 0 | R12: =P12-Q12 -> 0 | S12: =VLOOKUP(PPT!$F12,'LCB MIS overall'!$K$8:$BL$35,52,0)-VLOOKUP(PPT!$F12,'LCB MIS overall'!$K$8:$BL$35,53,0) -> 0 | T12: =VLOOKUP(PPT!$F12,'LCB MIS overall'!$K$8:$BL$35,54,0) -> 0 | U12: =S12-T12 -> 0 | AA12: 9 | AB12: 1.9 | AC12: WWNS | AD12: =AG12+AJ12+AM12+AP12 -> 3 | AE12: =AH12+AK12+AN12+AQ12 -> 0 | AF12: =AI12+AL12+AO12+AR12 -> 3 | AG12: 3 | AH12: 0 | AI12: 3 | AJ12: 0 | AK12: 0 | AL12: 0 | AM12: 0 | AN12: 0 | AO12: 0 | AP12: 0 | AQ12: 0 | AR12: 0
D13: 10 | E13: 1.10-1 | F13: 0CWT | G13: =J13+M13+P13+S13 -> 0 | H13: =K13+N13+Q13+T13 -> 0 | I13: =L13+O13+R13+U13 -> 0 | J13: =VLOOKUP(PPT!$F13,'LCB MIS overall'!$K$8:$BL$35,28,0)-VLOOKUP(PPT!$F13,'LCB MIS overall'!$K$8:$BL$35,29,0) -> 0 | K13: =VLOOKUP(PPT!$F13,'LCB MIS overall'!$K$8:$BL$35,30,0) -> 0 | L13: =J13-K13 -> 0 | M13: =VLOOKUP(PPT!$F13,'LCB MIS overall'!$K$8:$BL$35,36,0)-VLOOKUP(PPT!$F13,'LCB MIS overall'!$K$8:$BL$35,37,0) -> 0 | N13: =VLOOKUP(PPT!$F13,'LCB MIS overall'!$K$8:$BL$35,38,0) -> 0 | O13: =M13-N13 -> 0 | P13: =VLOOKUP(PPT!$F13,'LCB MIS overall'!$K$8:$BL$35,44,0)-VLOOKUP(PPT!$F13,'LCB MIS overall'!$K$8:$BL$35,45,0) -> 0 | Q13: =VLOOKUP(PPT!$F13,'LCB MIS overall'!$K$8:$BL$35,46,0) -> 0 | R13: =P13-Q13 -> 0 | S13: =VLOOKUP(PPT!$F13,'LCB MIS overall'!$K$8:$BL$35,52,0)-VLOOKUP(PPT!$F13,'LCB MIS overall'!$K$8:$BL$35,53,0) -> 0 | T13: =VLOOKUP(PPT!$F13,'LCB MIS overall'!$K$8:$BL$35,54,0) -> 0 | U13: =S13-T13 -> 0 | AA13: 10 | AB13: 1.10-1 | AC13: 0CWT | AD13: =AG13+AJ13+AM13+AP13 -> 0 | AE13: =AH13+AK13+AN13+AQ13 -> 0 | AF13: =AI13+AL13+AO13+AR13 -> 0 | AG13: 0 | AH13: 0 | AI13: 0 | AJ13: 0 | AK13: 0 | AL13: 0 | AM13: 0 | AN13: 0 | AO13: 0 | AP13: 0 | AQ13: 0 | AR13: 0
D14: 11 | E14: 1.11 | F14: BURIED PIPING | G14: =J14+M14+P14+S14 -> 1 | H14: =K14+N14+Q14+T14 -> 0 | I14: =L14+O14+R14+U14 -> 1 | J14: =VLOOKUP(PPT!$F14,'LCB MIS overall'!$K$8:$BL$35,28,0)-VLOOKUP(PPT!$F14,'LCB MIS overall'!$K$8:$BL$35,29,0) -> 0 | K14: =VLOOKUP(PPT!$F14,'LCB MIS overall'!$K$8:$BL$35,30,0) -> 0 | L14: =J14-K14 -> 0 | M14: =VLOOKUP(PPT!$F14,'LCB MIS overall'!$K$8:$BL$35,36,0)-VLOOKUP(PPT!$F14,'LCB MIS overall'!$K$8:$BL$35,37,0) -> 1 | N14: =VLOOKUP(PPT!$F14,'LCB MIS overall'!$K$8:$BL$35,38,0) -> 0 | O14: =M14-N14 -> 1 | P14: =VLOOKUP(PPT!$F14,'LCB MIS overall'!$K$8:$BL$35,44,0)-VLOOKUP(PPT!$F14,'LCB MIS overall'!$K$8:$BL$35,45,0) -> 0 | Q14: =VLOOKUP(PPT!$F14,'LCB MIS overall'!$K$8:$BL$35,46,0) -> 0 | R14: =P14-Q14 -> 0 | S14: =VLOOKUP(PPT!$F14,'LCB MIS overall'!$K$8:$BL$35,52,0)-VLOOKUP(PPT!$F14,'LCB MIS overall'!$K$8:$BL$35,53,0) -> 0 | T14: =VLOOKUP(PPT!$F14,'LCB MIS overall'!$K$8:$BL$35,54,0) -> 0 | U14: =S14-T14 -> 0 | AA14: 11 | AB14: 1.11 | AC14: BURIED PIPING | AD14: =AG14+AJ14+AM14+AP14 -> 1 | AE14: =AH14+AK14+AN14+AQ14 -> 0 | AF14: =AI14+AL14+AO14+AR14 -> 1 | AG14: 0 | AH14: 0 | AI14: 0 | AJ14: 1 | AK14: 0 | AL14: 1 | AM14: 0 | AN14: 0 | AO14: 0 | AP14: 0 | AQ14: 0 | AR14: 0
D15: 12 | E15: 1.12 | F15: OVERHEAD PIPING | G15: =J15+M15+P15+S15 -> 0 | H15: =K15+N15+Q15+T15 -> 0 | I15: =L15+O15+R15+U15 -> 0 | J15: =VLOOKUP(PPT!$F15,'LCB MIS overall'!$K$8:$BL$35,28,0)-VLOOKUP(PPT!$F15,'LCB MIS overall'!$K$8:$BL$35,29,0) -> 0 | K15: =VLOOKUP(PPT!$F15,'LCB MIS overall'!$K$8:$BL$35,30,0) -> 0 | L15: =J15-K15 -> 0 | M15: =VLOOKUP(PPT!$F15,'LCB MIS overall'!$K$8:$BL$35,36,0)-VLOOKUP(PPT!$F15,'LCB MIS overall'!$K$8:$BL$35,37,0) -> 0 | N15: =VLOOKUP(PPT!$F15,'LCB MIS overall'!$K$8:$BL$35,38,0) -> 0 | O15: =M15-N15 -> 0 | P15: =VLOOKUP(PPT!$F15,'LCB MIS overall'!$K$8:$BL$35,44,0)-VLOOKUP(PPT!$F15,'LCB MIS overall'!$K$8:$BL$35,45,0) -> 0 | Q15: =VLOOKUP(PPT!$F15,'LCB MIS overall'!$K$8:$BL$35,46,0) -> 0 | R15: =P15-Q15 -> 0 | S15: =VLOOKUP(PPT!$F15,'LCB MIS overall'!$K$8:$BL$35,52,0)-VLOOKUP(PPT!$F15,'LCB MIS overall'!$K$8:$BL$35,53,0) -> 0 | T15: =VLOOKUP(PPT!$F15,'LCB MIS overall'!$K$8:$BL$35,54,0) -> 0 | U15: =S15-T15 -> 0 | AA15: 12 | AB15: 1.12 | AC15: OVERHEAD PIPING | AD15: =AG15+AJ15+AM15+AP15 -> 0 | AE15: =AH15+AK15+AN15+AQ15 -> 0 | AF15: =AI15+AL15+AO15+AR15 -> 0 | AG15: 0 | AH15: 0 | AI15: 0 | AJ15: 0 | AK15: 0 | AL15: 0 | AM15: 0 | AN15: 0 | AO15: 0 | AP15: 0 | AQ15: 0 | AR15: 0
D16: 13 | E16: 1.13 | F16: 0 UBS | G16: =J16+M16+P16+S16 -> 34 | H16: =K16+N16+Q16+T16 -> 18 | I16: =L16+O16+R16+U16 -> 16 | J16: =VLOOKUP(PPT!$F16,'LCB MIS overall'!$K$8:$BL$35,28,0)-VLOOKUP(PPT!$F16,'LCB MIS overall'!$K$8:$BL$35,29,0) -> 1 | K16: =VLOOKUP(PPT!$F16,'LCB MIS overall'!$K$8:$BL$35,30,0) -> 0 | L16: =J16-K16 -> 1 | M16: =VLOOKUP(PPT!$F16,'LCB MIS overall'!$K$8:$BL$35,36,0)-VLOOKUP(PPT!$F16,'LCB MIS overall'!$K$8:$BL$35,37,0) -> 4 | N16: =VLOOKUP(PPT!$F16,'LCB MIS overall'!$K$8:$BL$35,38,0) -> 0 | O16: =M16-N16 -> 4 | P16: =VLOOKUP(PPT!$F16,'LCB MIS overall'!$K$8:$BL$35,44,0)-VLOOKUP(PPT!$F16,'LCB MIS overall'!$K$8:$BL$35,45,0) -> 29 | Q16: =VLOOKUP(PPT!$F16,'LCB MIS overall'!$K$8:$BL$35,46,0) -> 18 | R16: =P16-Q16 -> 11 | S16: =VLOOKUP(PPT!$F16,'LCB MIS overall'!$K$8:$BL$35,52,0)-VLOOKUP(PPT!$F16,'LCB MIS overall'!$K$8:$BL$35,53,0) -> 0 | T16: =VLOOKUP(PPT!$F16,'LCB MIS overall'!$K$8:$BL$35,54,0) -> 0 | U16: =S16-T16 -> 0 | AA16: 13 | AB16: 1.13 | AC16: 0 UBS | AD16: =AG16+AJ16+AM16+AP16 -> 33 | AE16: =AH16+AK16+AN16+AQ16 -> 17 | AF16: =AI16+AL16+AO16+AR16 -> 16 | AG16: 1 | AH16: 0 | AI16: 1 | AJ16: 3 | AK16: 0 | AL16: 3 | AM16: 29 | AN16: 17 | AO16: 12 | AP16: 0 | AQ16: 0 | AR16: 0
D17: 14 | E17: 1.14 | F17: 0 UCS | G17: =J17+M17+P17+S17 -> 5 | H17: =K17+N17+Q17+T17 -> 3 | I17: =L17+O17+R17+U17 -> 2 | J17: =VLOOKUP(PPT!$F17,'LCB MIS overall'!$K$8:$BL$35,28,0)-VLOOKUP(PPT!$F17,'LCB MIS overall'!$K$8:$BL$35,29,0) -> 1 | K17: =VLOOKUP(PPT!$F17,'LCB MIS overall'!$K$8:$BL$35,30,0) -> 0 | L17: =J17-K17 -> 1 | M17: =VLOOKUP(PPT!$F17,'LCB MIS overall'!$K$8:$BL$35,36,0)-VLOOKUP(PPT!$F17,'LCB MIS overall'!$K$8:$BL$35,37,0) -> 2 | N17: =VLOOKUP(PPT!$F17,'LCB MIS overall'!$K$8:$BL$35,38,0) -> 1 | O17: =M17-N17 -> 1 | P17: =VLOOKUP(PPT!$F17,'LCB MIS overall'!$K$8:$BL$35,44,0)-VLOOKUP(PPT!$F17,'LCB MIS overall'!$K$8:$BL$35,45,0) -> 0 | Q17: =VLOOKUP(PPT!$F17,'LCB MIS overall'!$K$8:$BL$35,46,0) -> 0 | R17: =P17-Q17 -> 0 | S17: =VLOOKUP(PPT!$F17,'LCB MIS overall'!$K$8:$BL$35,52,0)-VLOOKUP(PPT!$F17,'LCB MIS overall'!$K$8:$BL$35,53,0) -> 2 | T17: =VLOOKUP(PPT!$F17,'LCB MIS overall'!$K$8:$BL$35,54,0) -> 2 | U17: =S17-T17 -> 0 | AA17: 14 | AB17: 1.14 | AC17: 0 UCS | AD17: =AG17+AJ17+AM17+AP17 -> 4 | AE17: =AH17+AK17+AN17+AQ17 -> 3 | AF17: =AI17+AL17+AO17+AR17 -> 1 | AG17: 1 | AH17: 0 | AI17: 1 | AJ17: 1 | AK17: 1 | AL17: 0 | AM17: 0 | AN17: 0 | AO17: 0 | AP17: 2 | AQ17: 2 | AR17: 0
D18: 15 | E18: 1.15 | F18: 03 UGF | G18: =J18+M18+P18+S18 -> 10 | H18: =K18+N18+Q18+T18 -> 0 | I18: =L18+O18+R18+U18 -> 10 | J18: =VLOOKUP(PPT!$F18,'LCB MIS overall'!$K$8:$BL$35,28,0)-VLOOKUP(PPT!$F18,'LCB MIS overall'!$K$8:$BL$35,29,0) -> 2 | K18: =VLOOKUP(PPT!$F18,'LCB MIS overall'!$K$8:$BL$35,30,0) -> 0 | L18: =J18-K18 -> 2 | M18: =VLOOKUP(PPT!$F18,'LCB MIS overall'!$K$8:$BL$35,36,0)-VLOOKUP(PPT!$F18,'LCB MIS overall'!$K$8:$BL$35,37,0) -> 4 | N18: =VLOOKUP(PPT!$F18,'LCB MIS overall'!$K$8:$BL$35,38,0) -> 0 | O18: =M18-N18 -> 4 | P18: =VLOOKUP(PPT!$F18,'LCB MIS overall'!$K$8:$BL$35,44,0)-VLOOKUP(PPT!$F18,'LCB MIS overall'!$K$8:$BL$35,45,0) -> 2 | Q18: =VLOOKUP(PPT!$F18,'LCB MIS overall'!$K$8:$BL$35,46,0) -> 0 | R18: =P18-Q18 -> 2 | S18: =VLOOKUP(PPT!$F18,'LCB MIS overall'!$K$8:$BL$35,52,0)-VLOOKUP(PPT!$F18,'LCB MIS overall'!$K$8:$BL$35,53,0) -> 2 | T18: =VLOOKUP(PPT!$F18,'LCB MIS overall'!$K$8:$BL$35,54,0) -> 0 | U18: =S18-T18 -> 2 | AA18: 15 | AB18: 1.15 | AC18: 03 UGF | AD18: =AG18+AJ18+AM18+AP18 -> 9 | AE18: =AH18+AK18+AN18+AQ18 -> 0 | AF18: =AI18+AL18+AO18+AR18 -> 9 | AG18: 2 | AH18: 0 | AI18: 2 | AJ18: 3 | AK18: 0 | AL18: 3 | AM18: 2 | AN18: 0 | AO18: 2 | AP18: 2 | AQ18: 0 | AR18: 2
D19: 16 | E19: 1.16 | F19: 01-02 UGH | G19: =J19+M19+P19+S19 -> 0 | H19: =K19+N19+Q19+T19 -> 0 | I19: =L19+O19+R19+U19 -> 0 | J19: =VLOOKUP(PPT!$F19,'LCB MIS overall'!$K$8:$BL$35,28,0)-VLOOKUP(PPT!$F19,'LCB MIS overall'!$K$8:$BL$35,29,0) -> 0 | K19: =VLOOKUP(PPT!$F19,'LCB MIS overall'!$K$8:$BL$35,30,0) -> 0 | L19: =J19-K19 -> 0 | M19: =VLOOKUP(PPT!$F19,'LCB MIS overall'!$K$8:$BL$35,36,0)-VLOOKUP(PPT!$F19,'LCB MIS overall'!$K$8:$BL$35,37,0) -> 0 | N19: =VLOOKUP(PPT!$F19,'LCB MIS overall'!$K$8:$BL$35,38,0) -> 0 | O19: =M19-N19 -> 0 | P19: =VLOOKUP(PPT!$F19,'LCB MIS overall'!$K$8:$BL$35,44,0)-VLOOKUP(PPT!$F19,'LCB MIS overall'!$K$8:$BL$35,45,0) -> 0 | Q19: =VLOOKUP(PPT!$F19,'LCB MIS overall'!$K$8:$BL$35,46,0) -> 0 | R19: =P19-Q19 -> 0 | S19: =VLOOKUP(PPT!$F19,'LCB MIS overall'!$K$8:$BL$35,52,0)-VLOOKUP(PPT!$F19,'LCB MIS overall'!$K$8:$BL$35,53,0) -> 0 | T19: =VLOOKUP(PPT!$F19,'LCB MIS overall'!$K$8:$BL$35,54,0) -> 0 | U19: =S19-T19 -> 0 | AA19: 16 | AB19: 1.16 | AC19: 01-02 UGH | AD19: =AG19+AJ19+AM19+AP19 -> 0 | AE19: =AH19+AK19+AN19+AQ19 -> 0 | AF19: =AI19+AL19+AO19+AR19 -> 0 | AG19: 0 | AH19: 0 | AI19: 0 | AJ19: 0 | AK19: 0 | AL19: 0 | AM19: 0 | AN19: 0 | AO19: 0 | AP19: 0 | AQ19: 0 | AR19: 0
D20: 17 | E20: 1.17 | F20: 03 UGU | G20: =J20+M20+P20+S20 -> 1 | H20: =K20+N20+Q20+T20 -> 0 | I20: =L20+O20+R20+U20 -> 1 | J20: =VLOOKUP(PPT!$F20,'LCB MIS overall'!$K$8:$BL$35,28,0)-VLOOKUP(PPT!$F20,'LCB MIS overall'!$K$8:$BL$35,29,0) -> 1 | K20: =VLOOKUP(PPT!$F20,'LCB MIS overall'!$K$8:$BL$35,30,0) -> 0 | L20: =J20-K20 -> 1 | M20: =VLOOKUP(PPT!$F20,'LCB MIS overall'!$K$8:$BL$35,36,0)-VLOOKUP(PPT!$F20,'LCB MIS overall'!$K$8:$BL$35,37,0) -> 0 | N20: =VLOOKUP(PPT!$F20,'LCB MIS overall'!$K$8:$BL$35,38,0) -> 0 | O20: =M20-N20 -> 0 | P20: =VLOOKUP(PPT!$F20,'LCB MIS overall'!$K$8:$BL$35,44,0)-VLOOKUP(PPT!$F20,'LCB MIS overall'!$K$8:$BL$35,45,0) -> 0 | Q20: =VLOOKUP(PPT!$F20,'LCB MIS overall'!$K$8:$BL$35,46,0) -> 0 | R20: =P20-Q20 -> 0 | S20: =VLOOKUP(PPT!$F20,'LCB MIS overall'!$K$8:$BL$35,52,0)-VLOOKUP(PPT!$F20,'LCB MIS overall'!$K$8:$BL$35,53,0) -> 0 | T20: =VLOOKUP(PPT!$F20,'LCB MIS overall'!$K$8:$BL$35,54,0) -> 0 | U20: =S20-T20 -> 0 | AA20: 17 | AB20: 1.17 | AC20: 03 UGU | AD20: =AG20+AJ20+AM20+AP20 -> 1 | AE20: =AH20+AK20+AN20+AQ20 -> 0 | AF20: =AI20+AL20+AO20+AR20 -> 1 | AG20: 1 | AH20: 0 | AI20: 1 | AJ20: 0 | AK20: 0 | AL20: 0 | AM20: 0 | AN20: 0 | AO20: 0 | AP20: 0 | AQ20: 0 | AR20: 0
D21: 18 | E21: 1.18 | F21: 0UQR | G21: =J21+M21+P21+S21 -> 0 | H21: =K21+N21+Q21+T21 -> 0 | I21: =L21+O21+R21+U21 -> 0 | J21: =VLOOKUP(PPT!$F21,'LCB MIS overall'!$K$8:$BL$35,28,0)-VLOOKUP(PPT!$F21,'LCB MIS overall'!$K$8:$BL$35,29,0) -> 0 | K21: =VLOOKUP(PPT!$F21,'LCB MIS overall'!$K$8:$BL$35,30,0) -> 0 | L21: =J21-K21 -> 0 | M21: =VLOOKUP(PPT!$F21,'LCB MIS overall'!$K$8:$BL$35,36,0)-VLOOKUP(PPT!$F21,'LCB MIS overall'!$K$8:$BL$35,37,0) -> 0 | N21: =VLOOKUP(PPT!$F21,'LCB MIS overall'!$K$8:$BL$35,38,0) -> 0 | O21: =M21-N21 -> 0 | P21: =VLOOKUP(PPT!$F21,'LCB MIS overall'!$K$8:$BL$35,44,0)-VLOOKUP(PPT!$F21,'LCB MIS overall'!$K$8:$BL$35,45,0) -> 0 | Q21: =VLOOKUP(PPT!$F21,'LCB MIS overall'!$K$8:$BL$35,46,0) -> 0 | R21: =P21-Q21 -> 0 | S21: =VLOOKUP(PPT!$F21,'LCB MIS overall'!$K$8:$BL$35,52,0)-VLOOKUP(PPT!$F21,'LCB MIS overall'!$K$8:$BL$35,53,0) -> 0 | T21: =VLOOKUP(PPT!$F21,'LCB MIS overall'!$K$8:$BL$35,54,0) -> 0 | U21: =S21-T21 -> 0 | AA21: 18 | AB21: 1.18 | AC21: 0UQR | AD21: =AG21+AJ21+AM21+AP21 -> 0 | AE21: =AH21+AK21+AN21+AQ21 -> 0 | AF21: =AI21+AL21+AO21+AR21 -> 0 | AG21: 0 | AH21: 0 | AI21: 0 | AJ21: 0 | AK21: 0 | AL21: 0 | AM21: 0 | AN21: 0 | AO21: 0 | AP21: 0 | AQ21: 0 | AR21: 0
D22: 19 | E22: 1.19 | F22: 0UTF | G22: =J22+M22+P22+S22 -> 0 | H22: =K22+N22+Q22+T22 -> 0 | I22: =L22+O22+R22+U22 -> 0 | J22: =VLOOKUP(PPT!$F22,'LCB MIS overall'!$K$8:$BL$35,28,0)-VLOOKUP(PPT!$F22,'LCB MIS overall'!$K$8:$BL$35,29,0) -> 0 | K22: =VLOOKUP(PPT!$F22,'LCB MIS overall'!$K$8:$BL$35,30,0) -> 0 | L22: =J22-K22 -> 0 | M22: =VLOOKUP(PPT!$F22,'LCB MIS overall'!$K$8:$BL$35,36,0)-VLOOKUP(PPT!$F22,'LCB MIS overall'!$K$8:$BL$35,37,0) -> 0 | N22: =VLOOKUP(PPT!$F22,'LCB MIS overall'!$K$8:$BL$35,38,0) -> 0 | O22: =M22-N22 -> 0 | P22: =VLOOKUP(PPT!$F22,'LCB MIS overall'!$K$8:$BL$35,44,0)-VLOOKUP(PPT!$F22,'LCB MIS overall'!$K$8:$BL$35,45,0) -> 0 | Q22: =VLOOKUP(PPT!$F22,'LCB MIS overall'!$K$8:$BL$35,46,0) -> 0 | R22: =P22-Q22 -> 0 | S22: =VLOOKUP(PPT!$F22,'LCB MIS overall'!$K$8:$BL$35,52,0)-VLOOKUP(PPT!$F22,'LCB MIS overall'!$K$8:$BL$35,53,0) -> 0 | T22: =VLOOKUP(PPT!$F22,'LCB MIS overall'!$K$8:$BL$35,54,0) -> 0 | U22: =S22-T22 -> 0 | AA22: 19 | AB22: 1.19 | AC22: 0UTF | AD22: =AG22+AJ22+AM22+AP22 -> 0 | AE22: =AH22+AK22+AN22+AQ22 -> 0 | AF22: =AI22+AL22+AO22+AR22 -> 0 | AG22: 0 | AH22: 0 | AI22: 0 | AJ22: 0 | AK22: 0 | AL22: 0 | AM22: 0 | AN22: 0 | AO22: 0 | AP22: 0 | AQ22: 0 | AR22: 0
D23: 20 | E23: 1.20-1 | F23: 0 UPK | G23: =J23+M23+P23+S23 -> 0 | H23: =K23+N23+Q23+T23 -> 0 | I23: =L23+O23+R23+U23 -> 0 | J23: =VLOOKUP(PPT!$F23,'LCB MIS overall'!$K$8:$BL$35,28,0)-VLOOKUP(PPT!$F23,'LCB MIS overall'!$K$8:$BL$35,29,0) -> 0 | K23: =VLOOKUP(PPT!$F23,'LCB MIS overall'!$K$8:$BL$35,30,0) -> 0 | L23: =J23-K23 -> 0 | M23: =VLOOKUP(PPT!$F23,'LCB MIS overall'!$K$8:$BL$35,36,0)-VLOOKUP(PPT!$F23,'LCB MIS overall'!$K$8:$BL$35,37,0) -> 0 | N23: =VLOOKUP(PPT!$F23,'LCB MIS overall'!$K$8:$BL$35,38,0) -> 0 | O23: =M23-N23 -> 0 | P23: =VLOOKUP(PPT!$F23,'LCB MIS overall'!$K$8:$BL$35,44,0)-VLOOKUP(PPT!$F23,'LCB MIS overall'!$K$8:$BL$35,45,0) -> 0 | Q23: =VLOOKUP(PPT!$F23,'LCB MIS overall'!$K$8:$BL$35,46,0) -> 0 | R23: =P23-Q23 -> 0 | S23: =VLOOKUP(PPT!$F23,'LCB MIS overall'!$K$8:$BL$35,52,0)-VLOOKUP(PPT!$F23,'LCB MIS overall'!$K$8:$BL$35,53,0) -> 0 | T23: =VLOOKUP(PPT!$F23,'LCB MIS overall'!$K$8:$BL$35,54,0) -> 0 | U23: =S23-T23 -> 0 | AA23: 20 | AB23: 1.20-1 | AC23: 0 UPK | AD23: =AG23+AJ23+AM23+AP23 -> 0 | AE23: =AH23+AK23+AN23+AQ23 -> 0 | AF23: =AI23+AL23+AO23+AR23 -> 0 | AG23: 0 | AH23: 0 | AI23: 0 | AJ23: 0 | AK23: 0 | AL23: 0 | AM23: 0 | AN23: 0 | AO23: 0 | AP23: 0 | AQ23: 0 | AR23: 0
D24: 21 | E24: 1.21 | F24: 0UKU | G24: =J24+M24+P24+S24 -> 0 | H24: =K24+N24+Q24+T24 -> 0 | I24: =L24+O24+R24+U24 -> 0 | J24: =VLOOKUP(PPT!$F24,'LCB MIS overall'!$K$8:$BL$35,28,0)-VLOOKUP(PPT!$F24,'LCB MIS overall'!$K$8:$BL$35,29,0) -> 0 | K24: =VLOOKUP(PPT!$F24,'LCB MIS overall'!$K$8:$BL$35,30,0) -> 0 | L24: =J24-K24 -> 0 | M24: =VLOOKUP(PPT!$F24,'LCB MIS overall'!$K$8:$BL$35,36,0)-VLOOKUP(PPT!$F24,'LCB MIS overall'!$K$8:$BL$35,37,0) -> 0 | N24: =VLOOKUP(PPT!$F24,'LCB MIS overall'!$K$8:$BL$35,38,0) -> 0 | O24: =M24-N24 -> 0 | P24: =VLOOKUP(PPT!$F24,'LCB MIS overall'!$K$8:$BL$35,44,0)-VLOOKUP(PPT!$F24,'LCB MIS overall'!$K$8:$BL$35,45,0) -> 0 | Q24: =VLOOKUP(PPT!$F24,'LCB MIS overall'!$K$8:$BL$35,46,0) -> 0 | R24: =P24-Q24 -> 0 | S24: =VLOOKUP(PPT!$F24,'LCB MIS overall'!$K$8:$BL$35,52,0)-VLOOKUP(PPT!$F24,'LCB MIS overall'!$K$8:$BL$35,53,0) -> 0 | T24: =VLOOKUP(PPT!$F24,'LCB MIS overall'!$K$8:$BL$35,54,0) -> 0 | U24: =S24-T24 -> 0 | AA24: 21 | AB24: 1.21 | AC24: 0UKU | AD24: =AG24+AJ24+AM24+AP24 -> 0 | AE24: =AH24+AK24+AN24+AQ24 -> 0 | AF24: =AI24+AL24+AO24+AR24 -> 0 | AG24: 0 | AH24: 0 | AI24: 0 | AJ24: 0 | AK24: 0 | AL24: 0 | AM24: 0 | AN24: 0 | AO24: 0 | AP24: 0 | AQ24: 0 | AR24: 0
D25: 22 | E25: 1.22 | F25: 0 UYB | G25: =J25+M25+P25+S25 -> 0 | H25: =K25+N25+Q25+T25 -> 0 | I25: =L25+O25+R25+U25 -> 0 | J25: =VLOOKUP(PPT!$F25,'LCB MIS overall'!$K$8:$BL$35,28,0)-VLOOKUP(PPT!$F25,'LCB MIS overall'!$K$8:$BL$35,29,0) -> 0 | K25: =VLOOKUP(PPT!$F25,'LCB MIS overall'!$K$8:$BL$35,30,0) -> 0 | L25: =J25-K25 -> 0 | M25: =VLOOKUP(PPT!$F25,'LCB MIS overall'!$K$8:$BL$35,36,0)-VLOOKUP(PPT!$F25,'LCB MIS overall'!$K$8:$BL$35,37,0) -> 0 | N25: =VLOOKUP(PPT!$F25,'LCB MIS overall'!$K$8:$BL$35,38,0) -> 0 | O25: =M25-N25 -> 0 | P25: =VLOOKUP(PPT!$F25,'LCB MIS overall'!$K$8:$BL$35,44,0)-VLOOKUP(PPT!$F25,'LCB MIS overall'!$K$8:$BL$35,45,0) -> 0 | Q25: =VLOOKUP(PPT!$F25,'LCB MIS overall'!$K$8:$BL$35,46,0) -> 0 | R25: =P25-Q25 -> 0 | S25: =VLOOKUP(PPT!$F25,'LCB MIS overall'!$K$8:$BL$35,52,0)-VLOOKUP(PPT!$F25,'LCB MIS overall'!$K$8:$BL$35,53,0) -> 0 | T25: =VLOOKUP(PPT!$F25,'LCB MIS overall'!$K$8:$BL$35,54,0) -> 0 | U25: =S25-T25 -> 0 | AA25: 22 | AB25: 1.22 | AC25: 0 UYB | AD25: =AG25+AJ25+AM25+AP25 -> 0 | AE25: =AH25+AK25+AN25+AQ25 -> 0 | AF25: =AI25+AL25+AO25+AR25 -> 0 | AG25: 0 | AH25: 0 | AI25: 0 | AJ25: 0 | AK25: 0 | AL25: 0 | AM25: 0 | AN25: 0 | AO25: 0 | AP25: 0 | AQ25: 0 | AR25: 0
D26: 23 | E26: 1.23 | F26: 0 USV | G26: =J26+M26+P26+S26 -> 1 | H26: =K26+N26+Q26+T26 -> 0 | I26: =L26+O26+R26+U26 -> 1 | J26: =VLOOKUP(PPT!$F26,'LCB MIS overall'!$K$8:$BL$35,28,0)-VLOOKUP(PPT!$F26,'LCB MIS overall'!$K$8:$BL$35,29,0) -> 1 | K26: =VLOOKUP(PPT!$F26,'LCB MIS overall'!$K$8:$BL$35,30,0) -> 0 | L26: =J26-K26 -> 1 | M26: =VLOOKUP(PPT!$F26,'LCB MIS overall'!$K$8:$BL$35,36,0)-VLOOKUP(PPT!$F26,'LCB MIS overall'!$K$8:$BL$35,37,0) -> 0 | N26: =VLOOKUP(PPT!$F26,'LCB MIS overall'!$K$8:$BL$35,38,0) -> 0 | O26: =M26-N26 -> 0 | P26: =VLOOKUP(PPT!$F26,'LCB MIS overall'!$K$8:$BL$35,44,0)-VLOOKUP(PPT!$F26,'LCB MIS overall'!$K$8:$BL$35,45,0) -> 0 | Q26: =VLOOKUP(PPT!$F26,'LCB MIS overall'!$K$8:$BL$35,46,0) -> 0 | R26: =P26-Q26 -> 0 | S26: =VLOOKUP(PPT!$F26,'LCB MIS overall'!$K$8:$BL$35,52,0)-VLOOKUP(PPT!$F26,'LCB MIS overall'!$K$8:$BL$35,53,0) -> 0 | T26: =VLOOKUP(PPT!$F26,'LCB MIS overall'!$K$8:$BL$35,54,0) -> 0 | U26: =S26-T26 -> 0 | AA26: 23 | AB26: 1.23 | AC26: 0 USV | AD26: =AG26+AJ26+AM26+AP26 -> 1 | AE26: =AH26+AK26+AN26+AQ26 -> 0 | AF26: =AI26+AL26+AO26+AR26 -> 1 | AG26: 1 | AH26: 0 | AI26: 1 | AJ26: 0 | AK26: 0 | AL26: 0 | AM26: 0 | AN26: 0 | AO26: 0 | AP26: 0 | AQ26: 0 | AR26: 0
D27: 24 | E27: 1.24 | F27: 02 UYE | G27: =J27+M27+P27+S27 -> 1 | H27: =K27+N27+Q27+T27 -> 0 | I27: =L27+O27+R27+U27 -> 1 | J27: =VLOOKUP(PPT!$F27,'LCB MIS overall'!$K$8:$BL$35,28,0)-VLOOKUP(PPT!$F27,'LCB MIS overall'!$K$8:$BL$35,29,0) -> 1 | K27: =VLOOKUP(PPT!$F27,'LCB MIS overall'!$K$8:$BL$35,30,0) -> 0 | L27: =J27-K27 -> 1 | M27: =VLOOKUP(PPT!$F27,'LCB MIS overall'!$K$8:$BL$35,36,0)-VLOOKUP(PPT!$F27,'LCB MIS overall'!$K$8:$BL$35,37,0) -> 0 | N27: =VLOOKUP(PPT!$F27,'LCB MIS overall'!$K$8:$BL$35,38,0) -> 0 | O27: =M27-N27 -> 0 | P27: =VLOOKUP(PPT!$F27,'LCB MIS overall'!$K$8:$BL$35,44,0)-VLOOKUP(PPT!$F27,'LCB MIS overall'!$K$8:$BL$35,45,0) -> 0 | Q27: =VLOOKUP(PPT!$F27,'LCB MIS overall'!$K$8:$BL$35,46,0) -> 0 | R27: =P27-Q27 -> 0 | S27: =VLOOKUP(PPT!$F27,'LCB MIS overall'!$K$8:$BL$35,52,0)-VLOOKUP(PPT!$F27,'LCB MIS overall'!$K$8:$BL$35,53,0) -> 0 | T27: =VLOOKUP(PPT!$F27,'LCB MIS overall'!$K$8:$BL$35,54,0) -> 0 | U27: =S27-T27 -> 0 | AA27: 24 | AB27: 1.24 | AC27: 02 UYE | AD27: =AG27+AJ27+AM27+AP27 -> 1 | AE27: =AH27+AK27+AN27+AQ27 -> 0 | AF27: =AI27+AL27+AO27+AR27 -> 1 | AG27: 1 | AH27: 0 | AI27: 1 | AJ27: 0 | AK27: 0 | AL27: 0 | AM27: 0 | AN27: 0 | AO27: 0 | AP27: 0 | AQ27: 0 | AR27: 0
D28: 25 | E28: 1.25 | F28: OST | G28: =J28+M28+P28+S28 -> 3 | H28: =K28+N28+Q28+T28 -> 0 | I28: =L28+O28+R28+U28 -> 3 | J28: =VLOOKUP(PPT!$F28,'LCB MIS overall'!$K$8:$BL$35,28,0)-VLOOKUP(PPT!$F28,'LCB MIS overall'!$K$8:$BL$35,29,0) -> 3 | K28: =VLOOKUP(PPT!$F28,'LCB MIS overall'!$K$8:$BL$35,30,0) -> 0 | L28: =J28-K28 -> 3 | M28: =VLOOKUP(PPT!$F28,'LCB MIS overall'!$K$8:$BL$35,36,0)-VLOOKUP(PPT!$F28,'LCB MIS overall'!$K$8:$BL$35,37,0) -> 0 | N28: =VLOOKUP(PPT!$F28,'LCB MIS overall'!$K$8:$BL$35,38,0) -> 0 | O28: =M28-N28 -> 0 | P28: =VLOOKUP(PPT!$F28,'LCB MIS overall'!$K$8:$BL$35,44,0)-VLOOKUP(PPT!$F28,'LCB MIS overall'!$K$8:$BL$35,45,0) -> 0 | Q28: =VLOOKUP(PPT!$F28,'LCB MIS overall'!$K$8:$BL$35,46,0) -> 0 | R28: =P28-Q28 -> 0 | S28: =VLOOKUP(PPT!$F28,'LCB MIS overall'!$K$8:$BL$35,52,0)-VLOOKUP(PPT!$F28,'LCB MIS overall'!$K$8:$BL$35,53,0) -> 0 | T28: =VLOOKUP(PPT!$F28,'LCB MIS overall'!$K$8:$BL$35,54,0) -> 0 | U28: =S28-T28 -> 0 | AA28: 25 | AB28: 1.25 | AC28: OST | AD28: =AG28+AJ28+AM28+AP28 -> 0 | AE28: =AH28+AK28+AN28+AQ28 -> 0 | AF28: =AI28+AL28+AO28+AR28 -> 0 | AG28: 0 | AH28: 0 | AI28: 0 | AJ28: 0 | AK28: 0 | AL28: 0 | AM28: 0 | AN28: 0 | AO28: 0 | AP28: 0 | AQ28: 0 | AR28: 0
D29: 26 | E29: 1.26 | F29: AUXILARY BUILDING AND STRUCTURES AREA FENCING ( 09UZJ) | G29: =J29+M29+P29+S29 -> 0 | H29: =K29+N29+Q29+T29 -> 0 | I29: =L29+O29+R29+U29 -> 0 | J29: =VLOOKUP(PPT!$F29,'LCB MIS overall'!$K$8:$BL$35,28,0)-VLOOKUP(PPT!$F29,'LCB MIS overall'!$K$8:$BL$35,29,0) -> 0 | K29: =VLOOKUP(PPT!$F29,'LCB MIS overall'!$K$8:$BL$35,30,0) -> 0 | L29: =J29-K29 -> 0 | M29: =VLOOKUP(PPT!$F29,'LCB MIS overall'!$K$8:$BL$35,36,0)-VLOOKUP(PPT!$F29,'LCB MIS overall'!$K$8:$BL$35,37,0) -> 0 | N29: =VLOOKUP(PPT!$F29,'LCB MIS overall'!$K$8:$BL$35,38,0) -> 0 | O29: =M29-N29 -> 0 | P29: =VLOOKUP(PPT!$F29,'LCB MIS overall'!$K$8:$BL$35,44,0)-VLOOKUP(PPT!$F29,'LCB MIS overall'!$K$8:$BL$35,45,0) -> 0 | Q29: =VLOOKUP(PPT!$F29,'LCB MIS overall'!$K$8:$BL$35,46,0) -> 0 | R29: =P29-Q29 -> 0 | S29: =VLOOKUP(PPT!$F29,'LCB MIS overall'!$K$8:$BL$35,52,0)-VLOOKUP(PPT!$F29,'LCB MIS overall'!$K$8:$BL$35,53,0) -> 0 | T29: =VLOOKUP(PPT!$F29,'LCB MIS overall'!$K$8:$BL$35,54,0) -> 0 | U29: =S29-T29 -> 0 | AA29: 26 | AB29: 1.26 | AC29: AUXILARY BUILDING AND STRUCTURES AREA FENCING | AD29: =AG29+AJ29+AM29+AP29 -> 0 | AE29: =AH29+AK29+AN29+AQ29 -> 0 | AF29: =AI29+AL29+AO29+AR29 -> 0 | AG29: 0 | AH29: 0 | AI29: 0 | AJ29: 0 | AK29: 0 | AL29: 0 | AM29: 0 | AN29: 0 | AO29: 0 | AP29: 0 | AQ29: 0 | AR29: 0
D30: 27 | E30: 1.27 | F30: EXTENDED PORTION OF 0 UKU | G30: =J30+M30+P30+S30 -> 0 | H30: =K30+N30+Q30+T30 -> 0 | I30: =L30+O30+R30+U30 -> 0 | J30: =VLOOKUP(PPT!$F30,'LCB MIS overall'!$K$8:$BL$35,28,0)-VLOOKUP(PPT!$F30,'LCB MIS overall'!$K$8:$BL$35,29,0) -> 0 | K30: =VLOOKUP(PPT!$F30,'LCB MIS overall'!$K$8:$BL$35,30,0) -> 0 | L30: =J30-K30 -> 0 | M30: =VLOOKUP(PPT!$F30,'LCB MIS overall'!$K$8:$BL$35,36,0)-VLOOKUP(PPT!$F30,'LCB MIS overall'!$K$8:$BL$35,37,0) -> 0 | N30: =VLOOKUP(PPT!$F30,'LCB MIS overall'!$K$8:$BL$35,38,0) -> 0 | O30: =M30-N30 -> 0 | P30: =VLOOKUP(PPT!$F30,'LCB MIS overall'!$K$8:$BL$35,44,0)-VLOOKUP(PPT!$F30,'LCB MIS overall'!$K$8:$BL$35,45,0) -> 0 | Q30: =VLOOKUP(PPT!$F30,'LCB MIS overall'!$K$8:$BL$35,46,0) -> 0 | R30: =P30-Q30 -> 0 | S30: =VLOOKUP(PPT!$F30,'LCB MIS overall'!$K$8:$BL$35,52,0)-VLOOKUP(PPT!$F30,'LCB MIS overall'!$K$8:$BL$35,53,0) -> 0 | T30: =VLOOKUP(PPT!$F30,'LCB MIS overall'!$K$8:$BL$35,54,0) -> 0 | U30: =S30-T30 -> 0 | AA30: 27 | AB30: 1.27 | AC30: EXTENDED PORTION OF 0 UKU | AD30: =AG30+AJ30+AM30+AP30 -> 0 | AE30: =AH30+AK30+AN30+AQ30 -> 0 | AF30: =AI30+AL30+AO30+AR30 -> 0 | AG30: 0 | AH30: 0 | AI30: 0 | AJ30: 0 | AK30: 0 | AL30: 0 | AM30: 0 | AN30: 0 | AO30: 0 | AP30: 0 | AQ30: 0 | AR30: 0

Sheet LCB MIS overall
I1: DEMO COPY
I2: Construction Completion Certificate (CCC)
I4: FOR OAC | BO4: 46039
L5: CCC | X5: Quality HO | Z5: Quality HO | AB5: History Docket | AI5: Civil | AQ5: Mechanical | AY5: Electrical | BG5: C&I
B6: C1 | H6: C | L6: =SUM(L8:L35) -> 665 | M6: =SUM(M8:M35) -> 134 | N6: =SUM(N8:N35) -> 110 | O6: =SUM(O8:O35) -> 52 | P6: =SUM(P8:P35) -> 114 | Q6: =SUM(Q8:Q35) -> 6 | S6: =SUM(S8:S35) -> 39 | U6: =SUM(U8:U35) -> 20 | V6: =SUM(V8:V35) -> 18 | W6: =SUM(W8:W35) -> 93 | X6: =SUM(X8:X35) -> 594 | Y6: =SUM(Y8:Y35) -> 18 | Z6: =SUM(Z8:Z35) -> 576 | AB6: =SUM(AB8:AB35) -> 598 | AC6: =SUM(AC8:AC35) -> 310 | AD6: =SUM(AD8:AD35) -> 271 | AE6: =SUM(AE8:AE35) -> 39 | AF6: =SUM(AF8:AF35) -> 288 | AI6: =SUM(AI8:AI35) -> 75 | AJ6: =SUM(AJ8:AJ35) -> 45 | AK6: =SUM(AK8:AK35) -> 31 | AL6: =SUM(AL8:AL35) -> 35 | AM6: =SUM(AM8:AM35) -> 0 | AN6: =SUM(AN8:AN35) -> 0 | AQ6: =SUM(AQ8:AQ35) -> 308 | AR6: =SUM(AR8:AR35) -> 47 | AS6: =SUM(AS8:AS35) -> 41 | AT6: =SUM(AT8:AT35) -> 39 | AU6: =SUM(AU8:AU35) -> 6 | AV6: =SUM(AV8:AV35) -> 6 | AY6: =SUM(AY8:AY35) -> 151 | AZ6: =SUM(AZ8:AZ35) -> 14 | BA6: =SUM(BA8:BA35) -> 34 | BB6: =SUM(BB8:BB35) -> 31 | BC6: =SUM(BC8:BC35) -> 0 | BD6: =SUM(BD8:BD35) -> 18 | BG6: =SUM(BG8:BG35) -> 136 | BH6: =SUM(BH8:BH35) -> 2 | BI6: =SUM(BI8:BI35) -> 4 | BJ6: =SUM(BJ8:BJ35) -> 4 | BK6: =SUM(BK8:BK35) -> 0 | BL6: =SUM(BL8:BL35) -> 2
E7: 1 | F7: 2 | I7: Sl No | J7: System NO | K7: Description | L7: Scope | M7: Prepared | N7: received | O7: HD & Erection reports Available | P7: submitted | Q7: Returned | R7: Actual Submitted | S7: Approved | T7: Target Date of Sub | U7: Prepared beyond submitted | V7: HD Available, erection report required | W7: Erection reports Available, HD required | X7: Scope | Y7: received | Z7: Pending | AB7: Total HD | AC7: Submitted | AD7: Approved | AE7: To be Approved | AF7: To be Submitted | AH7: =SUM(AH8:AH35) -> 82 | AI7: Scope | AJ7: prepared | AK7: received | AL7: Submitted | AM7: Returned | AN7: Approved | AO7: Target Date of Sub | AP7: =SUM(AP8:AP35) -> 35 | AQ7: Scope | AR7: prepared | AS7: received | AT7: Submitted | AU7: Returned | AV7: Approved | AW7: Target Date of Sub | AX7: =SUM(AX8:AX35) -> 27 | AY7: Scope | AZ7: prepared | BA7: received | BB7: Submitted | BC7: Returned | BD7: Approved | BE7: Target Date of Sub | BF7: =SUM(BF8:BF35) -> 13 | BG7: Scope | BH7: prepared | BI7: received | BJ7: Submitted | BK7: Returned | BL7: Approved | BM7: Target Date of Sub | BN7: =SUM(BN8:BN35) -> 2 | BO7: Remarks
A8: NA | B8: Drawing List | D8: IPMIS ref No | F8: Erection reports | G8: Erection reports | H8: Submitted | I8: 1 | J8: 1.1 | K8: Desal | L8: =+COUNTIFS('CCC status Master'!$F$14:$F$707,'LCB MIS overall'!J8) -> 27 | M8: =+COUNTIFS('CCC status Master'!$F$14:$F$707,'LCB MIS overall'!$J8,'CCC status Master'!$AH$14:$AH$707,"Prepared")+COUNTIFS('CCC status Master'!$F$14:$F$707,'LCB MIS overall'!$J8,'CCC status Master'!$AH$14:$AH$707,"Submitted")+COUNTIFS('CCC status Master'!$AH$14:$AH$707,"approved",'CCC status Master'!$F$14:$F$707,'LCB MIS overall'!J8) -> 14 | N8: =+AK8+AS8+BA8+BI8 -> 15 | O8: =+COUNTIFS('CCC status Master'!AI$14:AI$707,"available",'CCC status Master'!$F$14:$F$707,'LCB MIS overall'!J8) -> 12 | P8: =+COUNTIFS('CCC status Master'!$F$14:$F$707,'LCB MIS overall'!J8,'CCC status Master'!$AH$14:$AH$707,'LCB MIS overall'!$H$8)+COUNTIFS('CCC status Master'!$AH$14:$AH$707,"approved",'CCC status Master'!$F$14:$F$707,'LCB MIS overall'!$J8) -> 14 | Q8: =+AM8+AU8+BC8+BK8 -> 1 | R8: =P8-Q8 -> 13 | S8: =+COUNTIFS('CCC status Master'!$F$14:$F$707,'LCB MIS overall'!J8,'CCC status Master'!$AH$14:$AH$707,'LCB MIS overall'!$A$9) -> 4 | T8: =+'1.1'!AJ12 -> 45925 | U8: =+COUNTIFS('CCC status Master'!$F$14:$F$707,'LCB MIS overall'!J8,'CCC status Master'!$AH$14:$AH$707,'LCB MIS overall'!$H$11) -> 0 | V8: =+COUNTIFS('CCC status Master'!AJ$14:AJ$707,"available",'CCC status Master'!$F$14:$F$707,'LCB MIS overall'!J8) -> 8 | W8: =+COUNTIFS('CCC status Master'!AK$14:AK$707,"available",'CCC status Master'!$F$14:$F$707,'LCB MIS overall'!J8) -> 15 | X8: =+COUNTIFS('CCC status Master'!$F$14:$F$707,'LCB MIS overall'!J8)-COUNTIFS('CCC status Master'!$F$14:$F$707,'LCB MIS overall'!J8,'CCC status Master'!$AN$14:$AN$707,"NA") -> 23 | Y8: =+COUNTIFS('CCC status Master'!$F$14:$F$707,'LCB MIS overall'!J8,'CCC status Master'!$AN$14:$AN$707,"received") -> 8 | Z8: =+X8-Y8 -> 15 | AB8: =+reference!I6 -> 34 | AC8: =+reference!J6 -> 30 | AD8: =+reference!K6 -> 28 | AE8: =+reference!L6 -> 2 | AF8: =+reference!M6 -> 4 | AH8: =AD8-AE8-AF8 -> 22 | AI8: =+$L8-COUNTIFS('CCC status Master'!$AO$14:$AO$707,"NA",'CCC status Master'!$F$14:$F$707,'LCB MIS overall'!$J8) -> 4 | AJ8: =+COUNTIFS('CCC status Master'!$F$14:$F$707,'LCB MIS overall'!$J8,'CCC status Master'!$AH$14:$AH$707,"prepared",'CCC status Master'!$C$14:$C$707,"civil")+COUNTIFS('CCC status Master'!$F$14:$F$707,'LCB MIS overall'!$J8,'CCC status Master'!$AH$14:$AH$707,"submitted",'CCC status Master'!$C$14:$C$707,"civil") -> 4 | AK8: =+COUNTIFS('CCC status Master'!$F$14:$F$707,'LCB MIS overall'!$J8,'CCC status Master'!$AO$14:$AO$707,"received") -> 4 | AL8: =+COUNTIFS('CCC status Master'!$F$14:$F$707,'LCB MIS overall'!$J8,'CCC status Master'!$AH$14:$AH$707,"submitted",'CCC status Master'!$C$14:$C$707,"Civil")+COUNTIFS('CCC status Master'!$AH$14:$AH$707,"approved",'CCC status Master'!$F$14:$F$707,'LCB MIS overall'!$J8,'CCC status Master'!$C$14:$C$707,"Civil") -> 4 | AM8: =+COUNTIFS('CCC status Master'!$AT$14:$AT$996,"returned",'CCC status Master'!$F$14:$F$996,'LCB MIS overall'!$J8,'CCC status Master'!$C$14:$C$996,"civil") -> 0 | AN8: =+COUNTIFS('CCC status Master'!$AH$14:$AH$986,"approved",'CCC status Master'!$F$14:$F$986,'LCB MIS overall'!$J8,'CCC status Master'!$C$14:$C$986,"Civil") -> 0 | AP8: =AL8-AM8-AN8 -> 4 | AQ8: =+$L8-COUNTIFS('CCC status Master'!$AP$14:$AP$707,"NA",'CCC status Master'!$F$14:$F$707,'LCB MIS overall'!$J8) -> 11 | AR8: =+COUNTIFS('CCC status Master'!$F$14:$F$707,'LCB MIS overall'!$J8,'CCC status Master'!$AH$14:$AH$707,"prepared",'CCC status Master'!$C$14:$C$707,"mech")+COUNTIFS('CCC status Master'!$F$14:$F$707,'LCB MIS overall'!$J8,'CCC status Master'!$AH$14:$AH$707,"submitted",'CCC status Master'!$C$14:$C$707,"mech") -> 6 | AS8: =+COUNTIFS('CCC status Master'!$F$14:$F$707,'LCB MIS overall'!$J8,'CCC status Master'!$AP$14:$AP$707,"received") -> 10 | AT8: =+COUNTIFS('CCC status Master'!$F$14:$F$707,'LCB MIS overall'!$J8,'CCC status Master'!$AH$14:$AH$707,"submitted",'CCC status Master'!$C$14:$C$707,"Mech")+AV8 -> 10 | AU8: =+COUNTIFS('CCC status Master'!$AT$14:$AT$996,"returned",'CCC status Master'!$F$14:$F$996,'LCB MIS overall'!$J8,'CCC status Master'!$C$14:$C$996,"Mech") -> 1 | AV8: =+COUNTIFS('CCC status Master'!$AH$14:$AH$986,"approved",'CCC status Master'!$F$14:$F$986,'LCB MIS overall'!$J8,'CCC status Master'!$C$14:$C$986,"Mech") -> 4 | AX8: =AT8-AU8-AV8 -> 5 | AY8: =+$L8-COUNTIFS('CCC status Master'!$AQ$14:$AQ$707,"NA",'CCC status Master'!$F$14:$F$707,'LCB MIS overall'!$J8) -> 6 | AZ8: =+COUNTIFS('CCC status Master'!$F$14:$F$707,'LCB MIS overall'!$J8,'CCC status Master'!$AH$14:$AH$707,"prepared",'CCC status Master'!$C$14:$C$707,"elec")+COUNTIFS('CCC status Master'!$F$14:$F$707,'LCB MIS overall'!$J8,'CCC status Master'!$AH$14:$AH$707,"submitted",'CCC status Master'!$C$14:$C$707,"elec") -> 0 | BA8: =+COUNTIFS('CCC status Master'!$F$14:$F$707,'LCB MIS overall'!$J8,'CCC status Master'!$AQ$14:$AQ$707,"received") -> 1 | BB8: =+COUNTIFS('CCC status Master'!$F$14:$F$707,'LCB MIS overall'!$J8,'CCC status Master'!$AH$14:$AH$707,"submitted",'CCC status Master'!$C$14:$C$707,"Elec")+COUNTIFS('CCC status Master'!$AH$14:$AH$707,"approved",'CCC status Master'!$F$14:$F$707,'LCB MIS overall'!$J8,'CCC status Master'!$C$14:$C$707,"Elec") -> 0 | BC8: =+COUNTIFS('CCC status Master'!$AT$14:$AT$996,"returned",'CCC status Master'!$F$14:$F$996,'LCB MIS overall'!$J8,'CCC status Master'!$C$14:$C$996,"Elec") -> 0 | BD8: =+COUNTIFS('CCC status Master'!$AH$14:$AH$986,"approved",'CCC status Master'!$F$14:$F$986,'LCB MIS overall'!$J8,'CCC status Master'!$C$14:$C$986,"Elec") -> 0 | BF8: =BB8-BC8-BD8 -> 0 | BG8: =+$L8-COUNTIFS('CCC status Master'!$AR$14:$AR$707,"NA",'CCC status Master'!$F$14:$F$707,'LCB MIS overall'!$J8) -> 6 | BH8: =+COUNTIFS('CCC status Master'!$F$14:$F$707,'LCB MIS overall'!$J8,'CCC status Master'!$AH$14:$AH$707,"prepared",'CCC status Master'!$C$14:$C$707,"C&I")+COUNTIFS('CCC status Master'!$F$14:$F$707,'LCB MIS overall'!$J8,'CCC status Master'!$AH$14:$AH$707,"submitted",'CCC status Master'!$C$14:$C$707,"c&I") -> 0 | BI8: =+COUNTIFS('CCC status Master'!$F$14:$F$707,'LCB MIS overall'!$J8,'CCC status Master'!$AR$14:$AR$707,"received") -> 0 | BJ8: =+COUNTIFS('CCC status Master'!$F$14:$F$707,'LCB MIS overall'!$J8,'CCC status Master'!$AH$14:$AH$707,"submitted",'CCC status Master'!$C$14:$C$707,"C&I")+BL8 -> 0 | BK8: =+COUNTIFS('CCC status Master'!$AT$14:$AT$996,"returned",'CCC status Master'!$F$14:$F$996,'LCB MIS overall'!$J8,'CCC status Master'!$C$14:$C$996,"c&I") -> 0 | BL8: =+COUNTIFS('CCC status Master'!$AH$14:$AH$986,"approved",'CCC status Master'!$F$14:$F$986,'LCB MIS overall'!$J8,'CCC status Master'!$C$14:$C$986,"C&I") -> 0 | BN8: =BJ8-BK8-BL8 -> 0 | BP8: =(AL8+AT8+BB8+BJ8)-P8 -> 0
A9: Approved | B9: Drawing List | D9: IPMIS ref No | F9: Erection reports | G9: Erection reports | H9: Priority | I9: 2 | J9: 1.2 | K9: DM | L9: =+COUNTIFS('CCC status Master'!$F$14:$F$707,'LCB MIS overall'!J9) -> 38 | M9: =+COUNTIFS('CCC status Master'!$F$14:$F$707,'LCB MIS overall'!$J9,'CCC status Master'!$AH$14:$AH$707,"Prepared")+COUNTIFS('CCC status Master'!$F$14:$F$707,'LCB MIS overall'!$J9,'CCC status Master'!$AH$14:$AH$707,"Submitted")+COUNTIFS('CCC status Master'!$AH$14:$AH$707,"approved",'CCC status Master'!$F$14:$F$707,'LCB MIS overall'!J9) -> 20 | N9: =+AK9+AS9+BA9+BI9 -> 17 | O9: =+COUNTIFS('CCC status Master'!AI$14:AI$707,"available",'CCC status Master'!$F$14:$F$707,'LCB MIS overall'!J9) -> 9 | P9: =+COUNTIFS('CCC status Master'!$F$14:$F$707,'LCB MIS overall'!J9,'CCC status Master'!$AH$14:$AH$707,'LCB MIS overall'!$H$8)+COUNTIFS('CCC status Master'!$AH$14:$AH$707,"approved",'CCC status Master'!$F$14:$F$707,'LCB MIS overall'!$J9) -> 16 | Q9: =+AM9+AU9+BC9+BK9 -> 0 | R9: =P9-Q9 -> 16 | S9: =+COUNTIFS('CCC status Master'!$F$14:$F$707,'LCB MIS overall'!J9,'CCC status Master'!$AH$14:$AH$707,'LCB MIS overall'!$A$9) -> 0 | T9: =+'1.2'!AJ11 -> 45920 | U9: =+COUNTIFS('CCC status Master'!$F$14:$F$707,'LCB MIS overall'!J9,'CCC status Master'!$AH$14:$AH$707,'LCB MIS overall'!$H$11) -> 4 | V9: =+COUNTIFS('CCC status Master'!AJ$14:AJ$707,"available",'CCC status Master'!$F$14:$F$707,'LCB MIS overall'!J9) -> 2 | W9: =+COUNTIFS('CCC status Master'!AK$14:AK$707,"available",'CCC status Master'!$F$14:$F$707,'LCB MIS overall'!J9) -> 17 | X9: =+COUNTIFS('CCC status Master'!$F$14:$F$707,'LCB MIS overall'!J9)-COUNTIFS('CCC status Master'!$F$14:$F$707,'LCB MIS overall'!J9,'CCC status Master'!$AN$14:$AN$707,"NA") -> 30 | Y9: =+COUNTIFS('CCC status Master'!$F$14:$F$707,'LCB MIS overall'!J9,'CCC status Master'!$AN$14:$AN$707,"received") -> 2 | Z9: =+X9-Y9 -> 28 | AB9: =+reference!I7 -> 39 | AC9: =+reference!J7 -> 31 | AD9: =+reference!K7 -> 30 | AE9: =+reference!L7 -> 1 | AF9: =+reference!M7 -> 8 | AH9: =+P9-Q9-S9 -> 16 | AI9: =+$L9-COUNTIFS('CCC status Master'!$AO$14:$AO$707,"NA",'CCC status Master'!$F$14:$F$707,'LCB MIS overall'!$J9) -> 8 | AJ9: =+COUNTIFS('CCC status Master'!$F$14:$F$707,'LCB MIS overall'!$J9,'CCC status Master'!$AH$14:$AH$707,"prepared",'CCC status Master'!$C$14:$C$707,"civil")+COUNTIFS('CCC status Master'!$F$14:$F$707,'LCB MIS overall'!$J9,'CCC status Master'!$AH$14:$AH$707,"submitted",'CCC status Master'!$C$14:$C$707,"civil") -> 8 | AK9: =+COUNTIFS('CCC status Master'!$F$14:$F$707,'LCB MIS overall'!$J9,'CCC status Master'!$AO$14:$AO$707,"received") -> 8 | AL9: =+COUNTIFS('CCC status Master'!$F$14:$F$707,'LCB MIS overall'!$J9,'CCC status Master'!$AH$14:$AH$707,"submitted",'CCC status Master'!$C$14:$C$707,"Civil") -> 8 | AM9: =+COUNTIFS('CCC status Master'!$AT$14:$AT$996,"returned",'CCC status Master'!$F$14:$F$996,'LCB MIS overall'!$J9,'CCC status Master'!$C$14:$C$996,"civil") -> 0 | AN9: =+COUNTIFS('CCC status Master'!$AH$14:$AH$986,"approved",'CCC status Master'!$F$14:$F$986,'LCB MIS overall'!$J9,'CCC status Master'!$C$14:$C$986,"Civil") -> 0 | AP9: =AL9-AM9-AN9 -> 8 | AQ9: =+$L9-COUNTIFS('CCC status Master'!$AP$14:$AP$707,"NA",'CCC status Master'!$F$14:$F$707,'LCB MIS overall'!$J9) -> 14 | AR9: =+COUNTIFS('CCC status Master'!$F$14:$F$707,'LCB MIS overall'!$J9,'CCC status Master'!$AH$14:$AH$707,"prepared",'CCC status Master'!$C$14:$C$707,"mech")+COUNTIFS('CCC status Master'!$F$14:$F$707,'LCB MIS overall'!$J9,'CCC status Master'!$AH$14:$AH$707,"submitted",'CCC status Master'!$C$14:$C$707,"mech") -> 12 | AS9: =+COUNTIFS('CCC status Master'!$F$14:$F$707,'LCB MIS overall'!$J9,'CCC status Master'!$AP$14:$AP$707,"received") -> 7 | AT9: =+COUNTIFS('CCC status Master'!$F$14:$F$707,'LCB MIS overall'!$J9,'CCC status Master'!$AH$14:$AH$707,"submitted",'CCC status Master'!$C$14:$C$707,"Mech")+AV9 -> 8 | AU9: =+COUNTIFS('CCC status Master'!$AT$14:$AT$996,"returned",'CCC status Master'!$F$14:$F$996,'LCB MIS overall'!$J9,'CCC status Master'!$C$14:$C$996,"Mech") -> 0 | AV9: =+COUNTIFS('CCC status Master'!$AH$14:$AH$986,"approved",'CCC status Master'!$F$14:$F$986,'LCB MIS overall'!$J9,'CCC status Master'!$C$14:$C$986,"Mech") -> 0 | AX9: =AT9-AU9-AV9 -> 8 | AY9: =+$L9-COUNTIFS('CCC status Master'!$AQ$14:$AQ$707,"NA",'CCC status Master'!$F$14:$F$707,'LCB MIS overall'!$J9) -> 6 | AZ9: =+COUNTIFS('CCC status Master'!$F$14:$F$707,'LCB MIS overall'!$J9,'CCC status Master'!$AH$14:$AH$707,"prepared",'CCC status Master'!$C$14:$C$707,"elec")+COUNTIFS('CCC status Master'!$F$14:$F$707,'LCB MIS overall'!$J9,'CCC status Master'!$AH$14:$AH$707,"submitted",'CCC status Master'!$C$14:$C$707,"elec") -> 0 | BA9: =+COUNTIFS('CCC status Master'!$F$14:$F$707,'LCB MIS overall'!$J9,'CCC status Master'!$AQ$14:$AQ$707,"received") -> 2 | BB9: =+COUNTIFS('CCC status Master'!$F$14:$F$707,'LCB MIS overall'!$J9,'CCC status Master'!$AH$14:$AH$707,"submitted",'CCC status Master'!$C$14:$C$707,"Elec")+COUNTIFS('CCC status Master'!$AH$14:$AH$707,"approved",'CCC status Master'!$F$14:$F$707,'LCB MIS overall'!$J9,'CCC status Master'!$C$14:$C$707,"Elec") -> 0 | BC9: =+COUNTIFS('CCC status Master'!$AT$14:$AT$996,"returned",'CCC status Master'!$F$14:$F$996,'LCB MIS overall'!$J9,'CCC status Master'!$C$14:$C$996,"Elec") -> 0 | BD9: =+COUNTIFS('CCC status Master'!$AH$14:$AH$986,"approved",'CCC status Master'!$F$14:$F$986,'LCB MIS overall'!$J9,'CCC status Master'!$C$14:$C$986,"Elec") -> 0 | BF9: =BB9-BC9-BD9 -> 0 | BG9: =+$L9-COUNTIFS('CCC status Master'!$AR$14:$AR$707,"NA",'CCC status Master'!$F$14:$F$707,'LCB MIS overall'!$J9) -> 10 | BH9: =+COUNTIFS('CCC status Master'!$F$14:$F$707,'LCB MIS overall'!$J9,'CCC status Master'!$AH$14:$AH$707,"prepared",'CCC status Master'!$C$14:$C$707,"C&I")+COUNTIFS('CCC status Master'!$F$14:$F$707,'LCB MIS overall'!$J9,'CCC status Master'!$AH$14:$AH$707,"submitted",'CCC status Master'!$C$14:$C$707,"c&I") -> 0 | BI9: =+COUNTIFS('CCC status Master'!$F$14:$F$707,'LCB MIS overall'!$J9,'CCC status Master'!$AR$14:$AR$707,"received") -> 0 | BJ9: =+COUNTIFS('CCC status Master'!$F$14:$F$707,'LCB MIS overall'!$J9,'CCC status Master'!$AH$14:$AH$707,"submitted",'CCC status Master'!$C$14:$C$707,"C&I")+BL9 -> 0 | BK9: =+COUNTIFS('CCC status Master'!$AT$14:$AT$996,"returned",'CCC status Master'!$F$14:$F$996,'LCB MIS overall'!$J9,'CCC status Master'!$C$14:$C$996,"c&I") -> 0 | BL9: =+COUNTIFS('CCC status Master'!$AH$14:$AH$986,"approved",'CCC status Master'!$F$14:$F$986,'LCB MIS overall'!$J9,'CCC status Master'!$C$14:$C$986,"C&I") -> 0 | BN9: =BJ9-BK9-BL9 -> 0 | BP9: =(AL9+AT9+BB9+BJ9)-P9 -> 0
A10: 16 | B10: Drawing List | D10: IPMIS ref No | F10: Erection reports | G10: Erection reports | H10: Npriority | I10: 3 | J10: 1.3 | K10: 01 UGD | L10: =+COUNTIFS('CCC status Master'!$F$14:$F$707,'LCB MIS overall'!J10) -> 22 | M10: =+COUNTIFS('CCC status Master'!$F$14:$F$707,'LCB MIS overall'!$J10,'CCC status Master'!$AH$14:$AH$707,"Prepared")+COUNTIFS('CCC status Master'!$F$14:$F$707,'LCB MIS overall'!$J10,'CCC status Master'!$AH$14:$AH$707,"Submitted")+COUNTIFS('CCC status Master'!$AH$14:$AH$707,"approved",'CCC status Master'!$F$14:$F$707,'LCB MIS overall'!J10) -> 3 | N10: =+AK10+AS10+BA10+BI10 -> 1 | O10: =+COUNTIFS('CCC status Master'!AI$14:AI$707,"available",'CCC status Master'!$F$14:$F$707,'LCB MIS overall'!J10) -> 1 | P10: =+COUNTIFS('CCC status Master'!$F$14:$F$707,'LCB MIS overall'!J10,'CCC status Master'!$AH$14:$AH$707,'LCB MIS overall'!$H$8)+COUNTIFS('CCC status Master'!$AH$14:$AH$707,"approved",'CCC status Master'!$F$14:$F$707,'LCB MIS overall'!$J10) -> 3 | Q10: =+AM10+AU10+BC10+BK10 -> 0 | R10: =P10-Q10 -> 3 | S10: =+COUNTIFS('CCC status Master'!$F$14:$F$707,'LCB MIS overall'!J10,'CCC status Master'!$AH$14:$AH$707,'LCB MIS overall'!$A$9) -> 0 | T10: =+'1.3'!AJ11 -> 45926 | U10: =+COUNTIFS('CCC status Master'!$F$14:$F$707,'LCB MIS overall'!J10,'CCC status Master'!$AH$14:$AH$707,'LCB MIS overall'!$H$11) -> 0 | V10: =+COUNTIFS('CCC status Master'!AJ$14:AJ$707,"available",'CCC status Master'!$F$14:$F$707,'LCB MIS overall'!J10) -> 0 | W10: =+COUNTIFS('CCC status Master'!AK$14:AK$707,"available",'CCC status Master'!$F$14:$F$707,'LCB MIS overall'!J10) -> 1 | X10: =+COUNTIFS('CCC status Master'!$F$14:$F$707,'LCB MIS overall'!J10)-COUNTIFS('CCC status Master'!$F$14:$F$707,'LCB MIS overall'!J10,'CCC status Master'!$AN$14:$AN$707,"NA") -> 21 | Y10: =+COUNTIFS('CCC status Master'!$F$14:$F$707,'LCB MIS overall'!J10,'CCC status Master'!$AN$14:$AN$707,"received") -> 0 | Z10: =+X10-Y10 -> 21 | AB10: =+reference!I8 -> 30 | AC10: =+reference!J8 -> 20 | AD10: =+reference!K8 -> 15 | AE10: =+reference!L8 -> 5 | AF10: =+reference!M8 -> 10 | AH10: =+P10-Q10-S10 -> 3 | AI10: =+$L10-COUNTIFS('CCC status Master'!$AO$14:$AO$707,"NA",'CCC status Master'!$F$14:$F$707,'LCB MIS overall'!$J10) -> 1 | AJ10: =+COUNTIFS('CCC status Master'!$F$14:$F$707,'LCB MIS overall'!$J10,'CCC status Master'!$AH$14:$AH$707,"prepared",'CCC status Master'!$C$14:$C$707,"civil")+COUNTIFS('CCC status Master'!$F$14:$F$707,'LCB MIS overall'!$J10,'CCC status Master'!$AH$14:$AH$707,"submitted",'CCC status Master'!$C$14:$C$707,"civil") -> 1 | AK10: =+COUNTIFS('CCC status Master'!$F$14:$F$707,'LCB MIS overall'!$J10,'CCC status Master'!$AO$14:$AO$707,"received") -> 1 | AL10: =+COUNTIFS('CCC status Master'!$F$14:$F$707,'LCB MIS overall'!$J10,'CCC status Master'!$AH$14:$AH$707,"submitted",'CCC status Master'!$C$14:$C$707,"Civil") -> 1 | AM10: =+COUNTIFS('CCC status Master'!$AT$14:$AT$996,"returned",'CCC status Master'!$F$14:$F$996,'LCB MIS overall'!$J10,'CCC status Master'!$C$14:$C$996,"civil") -> 0 | AN10: =+COUNTIFS('CCC status Master'!$AH$14:$AH$986,"approved",'CCC status Master'!$F$14:$F$986,'LCB MIS overall'!$J10,'CCC status Master'!$C$14:$C$986,"Civil") -> 0 | AP10: =AL10-AM10-AN10 -> 1 | AQ10: =+$L10-COUNTIFS('CCC status Master'!$AP$14:$AP$707,"NA",'CCC status Master'!$F$14:$F$707,'LCB MIS overall'!$J10) -> 16 | AR10: =+COUNTIFS('CCC status Master'!$F$14:$F$707,'LCB MIS overall'!$J10,'CCC status Master'!$AH$14:$AH$707,"prepared",'CCC status Master'!$C$14:$C$707,"mech")+COUNTIFS('CCC status Master'!$F$14:$F$707,'LCB MIS overall'!$J10,'CCC status Master'!$AH$14:$AH$707,"submitted",'CCC status Master'!$C$14:$C$707,"mech") -> 2 | AS10: =+COUNTIFS('CCC status Master'!$F$14:$F$707,'LCB MIS overall'!$J10,'CCC status Master'!$AP$14:$AP$707,"received") -> 0 | AT10: =+COUNTIFS('CCC status Master'!$F$14:$F$707,'LCB MIS overall'!$J10,'CCC status Master'!$AH$14:$AH$707,"submitted",'CCC status Master'!$C$14:$C$707,"Mech")+AV10 -> 2 | AU10: =+COUNTIFS('CCC status Master'!$AT$14:$AT$996,"returned",'CCC status Master'!$F$14:$F$996,'LCB MIS overall'!$J10,'CCC status Master'!$C$14:$C$996,"Mech") -> 0 | AV10: =+COUNTIFS('CCC status Master'!$AH$14:$AH$986,"approved",'CCC status Master'!$F$14:$F$986,'LCB MIS overall'!$J10,'CCC status Master'!$C$14:$C$986,"Mech") -> 0 | AX10: =AT10-AU10-AV10 -> 2 | AY10: =+$L10-COUNTIFS('CCC status Master'!$AQ$14:$AQ$707,"NA",'CCC status Master'!$F$14:$F$707,'LCB MIS overall'!$J10) -> 3 | AZ10: =+COUNTIFS('CCC status Master'!$F$14:$F$707,'LCB MIS overall'!$J10,'CCC status Master'!$AH$14:$AH$707,"prepared",'CCC status Master'!$C$14:$C$707,"elec")+COUNTIFS('CCC status Master'!$F$14:$F$707,'LCB MIS overall'!$J10,'CCC status Master'!$AH$14:$AH$707,"submitted",'CCC status Master'!$C$14:$C$707,"elec") -> 0 | BA10: =+COUNTIFS('CCC status Master'!$F$14:$F$707,'LCB MIS overall'!$J10,'CCC status Master'!$AQ$14:$AQ$707,"received") -> 0 | BB10: =+COUNTIFS('CCC status Master'!$F$14:$F$707,'LCB MIS overall'!$J10,'CCC status Master'!$AH$14:$AH$707,"submitted",'CCC status Master'!$C$14:$C$707,"Elec")+COUNTIFS('CCC status Master'!$AH$14:$AH$707,"approved",'CCC status Master'!$F$14:$F$707,'LCB MIS overall'!$J10,'CCC status Master'!$C$14:$C$707,"Elec") -> 0 | BC10: =+COUNTIFS('CCC status Master'!$AT$14:$AT$996,"returned",'CCC status Master'!$F$14:$F$996,'LCB MIS overall'!$J10,'CCC status Master'!$C$14:$C$996,"Elec") -> 0 | BD10: =+COUNTIFS('CCC status Master'!$AH$14:$AH$986,"approved",'CCC status Master'!$F$14:$F$986,'LCB MIS overall'!$J10,'CCC status Master'!$C$14:$C$986,"Elec") -> 0 | BF10: =BB10-BC10-BD10 -> 0 | BG10: =+$L10-COUNTIFS('CCC status Master'!$AR$14:$AR$707,"NA",'CCC status Master'!$F$14:$F$707,'LCB MIS overall'!$J10) -> 2 | BH10: =+COUNTIFS('CCC status Master'!$F$14:$F$707,'LCB MIS overall'!$J10,'CCC status Master'!$AH$14:$AH$707,"prepared",'CCC status Master'!$C$14:$C$707,"C&I")+COUNTIFS('CCC status Master'!$F$14:$F$707,'LCB MIS overall'!$J10,'CCC status Master'!$AH$14:$AH$707,"submitted",'CCC status Master'!$C$14:$C$707,"c&I") -> 0 | BI10: =+COUNTIFS('CCC status Master'!$F$14:$F$707,'LCB MIS overall'!$J10,'CCC status Master'!$AR$14:$AR$707,"received") -> 0 | BJ10: =+COUNTIFS('CCC status Master'!$F$14:$F$707,'LCB MIS overall'!$J10,'CCC status Master'!$AH$14:$AH$707,"submitted",'CCC status Master'!$C$14:$C$707,"C&I")+BL10 -> 0 | BK10: =+COUNTIFS('CCC status Master'!$AT$14:$AT$996,"returned",'CCC status Master'!$F$14:$F$996,'LCB MIS overall'!$J10,'CCC status Master'!$C$14:$C$996,"c&I") -> 0 | BL10: =+COUNTIFS('CCC status Master'!$AH$14:$AH$986,"approved",'CCC status Master'!$F$14:$F$986,'LCB MIS overall'!$J10,'CCC status Master'!$C$14:$C$986,"C&I") -> 0 | BN10: =BJ10-BK10-BL10 -> 0 | BP10: =(AL10+AT10+BB10+BJ10)-P10 -> 0
